2024-01-15 19:33:03,616 INFO    StreamThr :23400 [internal.py:wandb_internal():86] W&B internal server running at pid: 23400, started at: 2024-01-15 19:33:03.615679
2024-01-15 19:33:03,617 DEBUG   HandlerThread:23400 [handler.py:handle_request():146] handle_request: status
2024-01-15 19:33:03,621 INFO    WriterThread:23400 [datastore.py:open_for_write():85] open: D:\PythonPrograms\pytorch\pengge\U-Net-template\wandb\run-20240115_193303-zj7gg71a\run-zj7gg71a.wandb
2024-01-15 19:33:03,622 DEBUG   SenderThread:23400 [sender.py:send():382] send: header
2024-01-15 19:33:03,624 DEBUG   SenderThread:23400 [sender.py:send():382] send: run
2024-01-15 19:33:07,369 INFO    SenderThread:23400 [retry.py:__call__():172] Retry attempt failed:
Traceback (most recent call last):
  File "D:\Users\pengge\anaconda3\envs\pytorch\lib\site-packages\urllib3\connectionpool.py", line 712, in urlopen
    self._prepare_proxy(conn)
  File "D:\Users\pengge\anaconda3\envs\pytorch\lib\site-packages\urllib3\connectionpool.py", line 1012, in _prepare_proxy
    conn.connect()
  File "D:\Users\pengge\anaconda3\envs\pytorch\lib\site-packages\urllib3\connection.py", line 369, in connect
    self.sock = conn = self._connect_tls_proxy(hostname, conn)
  File "D:\Users\pengge\anaconda3\envs\pytorch\lib\site-packages\urllib3\connection.py", line 504, in _connect_tls_proxy
    socket = ssl_wrap_socket(
  File "D:\Users\pengge\anaconda3\envs\pytorch\lib\site-packages\urllib3\util\ssl_.py", line 453, in ssl_wrap_socket
    ssl_sock = _ssl_wrap_socket_impl(sock, context, tls_in_tls)
  File "D:\Users\pengge\anaconda3\envs\pytorch\lib\site-packages\urllib3\util\ssl_.py", line 495, in _ssl_wrap_socket_impl
    return ssl_context.wrap_socket(sock)
  File "D:\Users\pengge\anaconda3\envs\pytorch\lib\ssl.py", line 500, in wrap_socket
    return self.sslsocket_class._create(
  File "D:\Users\pengge\anaconda3\envs\pytorch\lib\ssl.py", line 1040, in _create
    self.do_handshake()
  File "D:\Users\pengge\anaconda3\envs\pytorch\lib\ssl.py", line 1309, in do_handshake
    self._sslobj.do_handshake()
ssl.SSLEOFError: EOF occurred in violation of protocol (_ssl.c:1129)

During handling of the above exception, another exception occurred:

Traceback (most recent call last):
  File "D:\Users\pengge\anaconda3\envs\pytorch\lib\site-packages\requests\adapters.py", line 440, in send
    resp = conn.urlopen(
  File "D:\Users\pengge\anaconda3\envs\pytorch\lib\site-packages\urllib3\connectionpool.py", line 799, in urlopen
    retries = retries.increment(
  File "D:\Users\pengge\anaconda3\envs\pytorch\lib\site-packages\urllib3\util\retry.py", line 592, in increment
    raise MaxRetryError(_pool, url, error or ResponseError(cause))
urllib3.exceptions.MaxRetryError: HTTPSConnectionPool(host='api.wandb.ai', port=443): Max retries exceeded with url: /graphql (Caused by SSLError(SSLEOFError(8, 'EOF occurred in violation of protocol (_ssl.c:1129)')))

During handling of the above exception, another exception occurred:

Traceback (most recent call last):
  File "D:\Users\pengge\anaconda3\envs\pytorch\lib\site-packages\wandb\sdk\lib\retry.py", line 131, in __call__
    result = self._call_fn(*args, **kwargs)
  File "D:\Users\pengge\anaconda3\envs\pytorch\lib\site-packages\wandb\sdk\internal\internal_api.py", line 369, in execute
    return self.client.execute(*args, **kwargs)  # type: ignore
  File "D:\Users\pengge\anaconda3\envs\pytorch\lib\site-packages\wandb\vendor\gql-0.2.0\wandb_gql\client.py", line 52, in execute
    result = self._get_result(document, *args, **kwargs)
  File "D:\Users\pengge\anaconda3\envs\pytorch\lib\site-packages\wandb\vendor\gql-0.2.0\wandb_gql\client.py", line 60, in _get_result
    return self.transport.execute(document, *args, **kwargs)
  File "D:\Users\pengge\anaconda3\envs\pytorch\lib\site-packages\wandb\sdk\lib\gql_request.py", line 58, in execute
    request = self.session.post(self.url, **post_args)
  File "D:\Users\pengge\anaconda3\envs\pytorch\lib\site-packages\requests\sessions.py", line 577, in post
    return self.request('POST', url, data=data, json=json, **kwargs)
  File "D:\Users\pengge\anaconda3\envs\pytorch\lib\site-packages\requests\sessions.py", line 529, in request
    resp = self.send(prep, **send_kwargs)
  File "D:\Users\pengge\anaconda3\envs\pytorch\lib\site-packages\requests\sessions.py", line 645, in send
    r = adapter.send(request, **kwargs)
  File "D:\Users\pengge\anaconda3\envs\pytorch\lib\site-packages\requests\adapters.py", line 517, in send
    raise SSLError(e, request=request)
requests.exceptions.SSLError: HTTPSConnectionPool(host='api.wandb.ai', port=443): Max retries exceeded with url: /graphql (Caused by SSLError(SSLEOFError(8, 'EOF occurred in violation of protocol (_ssl.c:1129)')))
2024-01-15 19:33:08,668 DEBUG   HandlerThread:23400 [handler.py:handle_request():146] handle_request: keepalive
2024-01-15 19:33:13,719 DEBUG   HandlerThread:23400 [handler.py:handle_request():146] handle_request: keepalive
2024-01-15 19:33:18,778 DEBUG   HandlerThread:23400 [handler.py:handle_request():146] handle_request: keepalive
2024-01-15 19:33:23,815 DEBUG   HandlerThread:23400 [handler.py:handle_request():146] handle_request: keepalive
2024-01-15 19:33:28,857 DEBUG   HandlerThread:23400 [handler.py:handle_request():146] handle_request: keepalive
2024-01-15 19:33:33,900 DEBUG   HandlerThread:23400 [handler.py:handle_request():146] handle_request: keepalive
2024-01-15 19:33:38,942 DEBUG   HandlerThread:23400 [handler.py:handle_request():146] handle_request: keepalive
2024-01-15 19:33:39,960 DEBUG   HandlerThread:23400 [handler.py:handle_request():146] handle_request: shutdown
2024-01-15 19:33:39,960 INFO    HandlerThread:23400 [handler.py:finish():866] shutting down handler
2024-01-15 19:33:40,958 INFO    WriterThread:23400 [datastore.py:close():294] close: D:\PythonPrograms\pytorch\pengge\U-Net-template\wandb\run-20240115_193303-zj7gg71a\run-zj7gg71a.wandb
